<testsuite errors="1" failures="0" name="unittest.suite.TestSuite" tests="1" time="0.001">
  <testcase classname="__main__.qa_Distance" name="test_001_t" time="0.0006">
    <error type="exceptions.TypeError">__init__() takes exactly 14 arguments (9 given)
  File "/usr/lib/python2.7/unittest/case.py", line 329, in run
    testMethod()
  File "/home/rich/Desktop/vlp_repos/gr-vlp/python/qa_Distance.py", line 48, in test_001_t
    distance = Distance (60, 0.098, 3, 1, 1.5, 90, 40, 1)
    </error>
  </testcase>
  <system-out><![CDATA[]]></system-out>
  <system-err><![CDATA[]]></system-err>
</testsuite>
